{
    "CVE_data_meta": {
        "ASSIGNER": "secalert@redhat.com",
        "ID": "CVE-2018-10855",
        "STATE": "PUBLIC",
        "UPDATED": "2020-06-15"
    },
    "cna-container": {
        "affected": {
            "vendors": [
                {
                    "products": [
                        {
                            "versions": [
                                {
                                    "version_value": "Ansible 2.4.5"
                                },
                                {
                                    "version_value": "Ansible 2.5.5"
                                }
                            ]
                        }
                    ],
                    "vendor_name": "[UNKNOWN]"
                }
            ]
        },
        "descriptions": [
            {
                "lang": "eng",
                "value": "Ansible 2.5 prior to 2.5.5, and 2.4 prior to 2.4.5, do not honor the no_log task flag for failed tasks. When the no_log flag has been used to protect sensitive data passed to a task from being logged, and that task does not run successfully, Ansible will expose sensitive data in log files and on the terminal of the user running Ansible."
            }
        ],
        "metrics": [
            {
                "cvss-v_3_0": {
                    "vectorString": "5.9/CVSS:3.0/AV:N/AC:H/PR:N/UI:N/S:U/C:H/I:N/A:N",
                    "version": "3.0"
                }
            }
        ],
        "problemtypes": {
            "descriptions": [
                [
                    {
                        "CWE-ID": "CWE-532",
                        "description": "CWE-532",
                        "lang": "eng",
                        "type": "CWE"
                    }
                ]
            ]
        },
        "references": [
            {
                "name": "RHSA-2018:1949",
                "refsource": "REDHAT",
                "url": "https://access.redhat.com/errata/RHSA-2018:1949"
            },
            {
                "name": "https://bugzilla.redhat.com/show_bug.cgi?id=CVE-2018-10855",
                "refsource": "CONFIRM",
                "url": "https://bugzilla.redhat.com/show_bug.cgi?id=CVE-2018-10855"
            },
            {
                "name": "RHBA-2018:3788",
                "refsource": "REDHAT",
                "url": "https://access.redhat.com/errata/RHBA-2018:3788"
            },
            {
                "name": "RHSA-2018:1948",
                "refsource": "REDHAT",
                "url": "https://access.redhat.com/errata/RHSA-2018:1948"
            },
            {
                "name": "RHSA-2018:2184",
                "refsource": "REDHAT",
                "url": "https://access.redhat.com/errata/RHSA-2018:2184"
            },
            {
                "name": "RHSA-2018:2022",
                "refsource": "REDHAT",
                "url": "https://access.redhat.com/errata/RHSA-2018:2022"
            },
            {
                "name": "RHSA-2019:0054",
                "refsource": "REDHAT",
                "url": "https://access.redhat.com/errata/RHSA-2019:0054"
            },
            {
                "name": "RHSA-2018:2079",
                "refsource": "REDHAT",
                "url": "https://access.redhat.com/errata/RHSA-2018:2079"
            },
            {
                "name": "RHSA-2018:2585",
                "refsource": "REDHAT",
                "url": "https://access.redhat.com/errata/RHSA-2018:2585"
            },
            {
                "name": "DSA-4396",
                "refsource": "DEBIAN",
                "url": "https://www.debian.org/security/2019/dsa-4396"
            },
            {
                "name": "USN-4072-1",
                "refsource": "UBUNTU",
                "url": "https://usn.ubuntu.com/4072-1/"
            }
        ]
    },
    "data_format": "MITRE",
    "data_type": "CVE",
    "data_version": "5.0"
}