{
    "CVE_data_meta": {
        "ASSIGNER": "cve@mitre.org",
        "ID": "CVE-2010-3495",
        "STATE": "PUBLIC",
        "UPDATED": "2020-06-15"
    },
    "cna-container": {
        "affected": {
            "vendors": [
                {
                    "products": [
                        {
                            "versions": [
                                {
                                    "version_value": "n/a"
                                }
                            ]
                        }
                    ],
                    "vendor_name": "n/a"
                }
            ]
        },
        "descriptions": [
            {
                "lang": "eng",
                "value": "Race condition in ZEO/StorageServer.py in Zope Object Database (ZODB) before 3.10.0 allows remote attackers to cause a denial of service (daemon outage) by establishing and then immediately closing a TCP connection, leading to the accept function having an unexpected return value of None, an unexpected value of None for the address, or an ECONNABORTED, EAGAIN, or EWOULDBLOCK error, a related issue to CVE-2010-3492."
            }
        ],
        "problemtypes": {
            "descriptions": [
                [
                    {
                        "description": "n/a",
                        "lang": "eng",
                        "type": "text"
                    }
                ]
            ]
        },
        "references": [
            {
                "name": "[oss-security] 20100910 Re: CVE Request -- Python -- accept() implementation in async core is broken => more subcases",
                "refsource": "MLIST",
                "url": "http://www.openwall.com/lists/oss-security/2010/09/11/2"
            },
            {
                "name": "https://bugs.launchpad.net/zodb/+bug/135108",
                "refsource": "CONFIRM",
                "url": "https://bugs.launchpad.net/zodb/+bug/135108"
            },
            {
                "name": "http://pypi.python.org/pypi/ZODB3/3.10.0#id1",
                "refsource": "CONFIRM",
                "url": "http://pypi.python.org/pypi/ZODB3/3.10.0#id1"
            },
            {
                "name": "[oss-security] 20100924 Re: CVE Request -- Python -- accept() implementation in async core is broken => more subcases",
                "refsource": "MLIST",
                "url": "http://www.openwall.com/lists/oss-security/2010/09/24/3"
            },
            {
                "name": "[oss-security] 20100922 Re: CVE Request -- Python -- accept() implementation in async core is broken => more subcases",
                "refsource": "MLIST",
                "url": "http://www.openwall.com/lists/oss-security/2010/09/22/3"
            },
            {
                "name": "http://bugs.python.org/issue6706",
                "refsource": "MISC",
                "url": "http://bugs.python.org/issue6706"
            },
            {
                "name": "[oss-security] 20100909 CVE Request -- Python -- accept() implementation in async core is broken => more subcases",
                "refsource": "MLIST",
                "url": "http://www.openwall.com/lists/oss-security/2010/09/09/6"
            },
            {
                "name": "SUSE-SR:2010:024",
                "refsource": "SUSE",
                "url": "http://lists.opensuse.org/opensuse-security-announce/2010-12/msg00006.html"
            },
            {
                "name": "41755",
                "refsource": "SECUNIA",
                "url": "http://secunia.com/advisories/41755"
            }
        ]
    },
    "data_format": "MITRE",
    "data_type": "CVE",
    "data_version": "5.0"
}